<?xml version="1.0"?>
<robot name="wheel" xmlns:xacro="http://www.ros.org/wiki/xacro">

  <xacro:property name="M_PI" value="3.1415926535897931" />
  <!-- Wheels -->
  <xacro:property name="wheel_radius" value="0.125" /> 
  <xacro:property name="wheel_height" value="0.14" /> <!-- really is the wheel width -->
  <xacro:property name="wheel_mass" value="6.5" /> <!-- in kg-->
 
 
  <xacro:macro name="cylinder_inertia" params="m r h">
    <inertia  ixx="${m*(3*r*r+h*h)/12}" ixy = "0" ixz = "0"
              iyy="${m*r*r/2}" iyz = "0"
              izz="${m*(3*r*r+h*h)/12}" /> 
  </xacro:macro>
 
  <xacro:macro name="rubber_wheel" params="prefix parent *origin reflect hq">
  
	<!--WHEEL TIRE -->
    <joint name="${prefix}_wheel_joint" type="continuous">
      <parent link="${parent}"/>
      <child link="${prefix}_wheel_link"/>
      <xacro:insert_block name="origin" />
      <axis xyz="0 0 1" rpy="0 0 0" />
      <limit effort="100" velocity="100"/>
      <joint_properties damping="0.0" friction="0.0"/>
    </joint>
  
    <link name="${prefix}_wheel_link">
      <visual>
        <!-- HIGH RESOLUTION WHEELS -->
        <xacro:if value="${hq}">
          <origin xyz="0 0 0" rpy="0 0 0" />
          <geometry>     
			<xacro:if value="${reflect}">
			 <mesh filename="package://rbsherpa_hl_description/meshes/wheels/rbsherpa_hl_wheel.dae" />
			</xacro:if>
			<xacro:unless value="${reflect}">
			 <mesh filename="package://rbsherpa_hl_description/meshes/wheels/rbsherpa_hl_wheel.dae" />
			</xacro:unless>
          </geometry>         
        </xacro:if>
       <!-- LOW RESOLUTION WHEELS -->
        <xacro:unless value="${hq}">
          <origin xyz="0 0 0" rpy="${M_PI/2} 0 0" />
          <geometry>           
            <cylinder length="${wheel_height}" radius="${wheel_radius}" />
          </geometry>      
        </xacro:unless>
      </visual>
      
      <collision>
		<origin xyz="0 0 0" rpy="${M_PI/2} 0 0" />
        <geometry>
			<mesh filename="package://rbsherpa_hl_description/meshes/wheels/rbsherpa_hl_motorwheel.stl" />
        </geometry>
      </collision>    
      <inertial>
        <mass value="${wheel_mass}" />
        <origin xyz="0 0 0" />
        <cylinder_inertia  m="${wheel_mass}" r="${wheel_radius}" h="${wheel_height}" />
      </inertial>
    </link>
  </xacro:macro>

</robot>
