<?xml version="1.0"?>
<robot name="steer_wheel" xmlns:xacro="http://www.ros.org/wiki/xacro">

  <xacro:include filename="$(find rbsherpa_hl_description)/urdf/wheels/steer_wheel.transmission.xacro"/>

  <xacro:property name="M_PI" value="3.1415926535897931" />
  <!-- Wheels -->
  <xacro:property name="wheel_radius" value="0.18415" />
  <xacro:property name="wheel_height" value="0.14" /> <!--TODO: Unknown --> <!-- really is the wheel width -->
  <xacro:property name="steer_joint_damping" value="0.01" />
  <xacro:property name="steer_joint_friction" value="0.01" />
  <xacro:property name="steer_joint_position_limit" value="2.9" /> 
   
  <xacro:macro name="steer_wheel" params="prefix parent *origin reflect hq">

	<!--WHEEL TIRE -->
    <joint name="${prefix}_wheel_joint" type="revolute">
      <parent link="${parent}"/>
      <child link="${prefix}_wheel_link"/>
      <xacro:insert_block name="origin" />
      <axis xyz="0 0 1" rpy="0 0 0" />
      <limit effort="100" velocity="50" lower="-${steer_joint_position_limit}" upper="${steer_joint_position_limit}"/>
      <joint_properties damping="${steer_joint_damping}" friction="${steer_joint_friction}"/>
    </joint>

    <link name="${prefix}_wheel_link">
      <visual>
        <!-- HIGH RESOLUTION WHEELS -->
        <xacro:if value="${hq}">
          <origin xyz="0 0 0" rpy="0 0 0" />
          <geometry>
			<xacro:if value="${reflect}">
			 <mesh filename="package://rbsherpa_hl_description/meshes/wheels/rbsherpa_hl_wheel.dae" />
			 <!--cylinder length="${wheel_height}" radius="${wheel_radius}" /-->
			</xacro:if>
			<xacro:unless value="${reflect}">
			 <mesh filename="package://rbsherpa_hl_description/meshes/wheels/rbsherpa_hl_wheel.dae" />
			 <!--cylinder length="${wheel_height}" radius="${wheel_radius}" /-->
			</xacro:unless>
          </geometry>
        </xacro:if>
       <!-- LOW RESOLUTION WHEELS -->
        <xacro:unless value="${hq}">
          <origin xyz="0 0 0" rpy="${M_PI/2} 0 0" />
          <geometry>
            <cylinder length="${wheel_height}" radius="${wheel_radius}" />
          </geometry>
        </xacro:unless>
      </visual>

      <collision>
		<origin xyz="0 0 0" rpy="0 0 0" />
        <geometry>
			<cylinder length="0.1" radius="0.1" />
        </geometry>
      </collision>
      <inertial>
      <mass value="37.29668" />
        <origin xyz="0.00122 -0.00633 0.07032" />
        <inertia  ixx="0.656095" ixy = "0.0002884484" ixz = "0.0037546231"
                  iyy="0.645381" iyz = "0.06221658"
                  izz="0.160381" />
      </inertial>
    </link>
        
    <xacro:steer_wheel_transmission prefix="${prefix}" />
    
  </xacro:macro>

</robot>
