<?xml version="1.0"?>
<robot name="pantilt" xmlns:xacro="http://ros.org/wiki/xacro">
  <xacro:property name="PI" value="3.1415926535897931"/>

  <xacro:macro name="pantilt" params="prefix parent hq">
 
    <joint name="${prefix}torso_pantilt_pan_joint" type="revolute">
      <origin xyz="-0.547 0.0 1.32" rpy="0 0 0"/>
      <parent link="${parent}"/>
      <child link="${prefix}torso_pantilt_pan_link"/>
      <axis xyz="0 0 1"/>
      <limit lower="-0.95" upper="0.95" effort="100" velocity="100"/>
      <dynamics friction="1000" damping="1000"/>
    </joint>
	
    <transmission name="${prefix}torso_pantilt_pan_trans">
        <type>transmission_interface/SimpleTransmission</type>
        <joint name="${prefix}torso_pantilt_pan_joint">
          <hardwareInterface>PositionJointInterface</hardwareInterface>
        </joint>
        <actuator name="${prefix}torso_pantilt_pan_motor">
          <mechanicalReduction>1</mechanicalReduction>
          <hardwareInterface>PositionJointInterface</hardwareInterface>
        </actuator>
    </transmission>
      
    <link name="${prefix}torso_pantilt_pan_link">
      <visual>
        <origin xyz="0 0 0" rpy="0 0 0"/>
        <geometry>
          <mesh filename="package://rbsherpa_hl_description/meshes/pantilt/pan_dynamixel.stl"/>
        </geometry>
        <material name="lightgrey">
          <color rgba="0.3 0.3 0.3 1"/>
        </material>
      </visual>
      <collision>
        <origin xyz="0 0 0" rpy="0 0 0"/>
        <geometry>
          <mesh filename="package://rbsherpa_hl_description/meshes/pantilt/pan_dynamixel.stl"/>
        </geometry>
      </collision>
      <inertial>
        <origin xyz="0 0 0" rpy="0 0 0"/>
        <mass value="5"/>
        <inertia ixx="1.0" ixy="0.0" ixz="0.0" iyy="1.0" iyz="0.0" izz="1.0"/>
      </inertial>
    </link>
    
    <!-- TILT JOINT/LINK -->
    <joint name="${prefix}torso_pantilt_tilt_joint" type="revolute">
      <origin xyz="0.0 0.0 0.126" rpy="0 0 0"/>
      <parent link="${prefix}torso_pantilt_pan_link"/>
      <child link="${prefix}torso_pantilt_tilt_link"/>
      <axis xyz="0 1 0"/>
      <limit lower="-0.26" upper="0.26" effort="100" velocity="100"/>
      <dynamics friction="1000" damping="1000"/>
    </joint>
	
	<transmission name="${prefix}torso_pantilt_tilt_trans">
      <type>transmission_interface/SimpleTransmission</type>
      <joint name="${prefix}torso_pantilt_tilt_joint">
        <hardwareInterface>PositionJointInterface</hardwareInterface>
      </joint>
      <actuator name="${prefix}torso_pantilt_tilt_motor">
        <mechanicalReduction>1</mechanicalReduction>
        <hardwareInterface>PositionJointInterface</hardwareInterface>
      </actuator>
    </transmission>
    
    <link name="${prefix}torso_pantilt_tilt_link">
      <visual>
        <origin xyz="0 0 0" rpy="0 0 0"/>
        <geometry>
          <mesh filename="package://rbsherpa_hl_description/meshes/pantilt/tilt_dynamixel.stl"/>
        </geometry>
       <material name="lightgrey">
         <color rgba="0.3 0.3 0.3 1"/>
       </material>
      </visual>
      <collision>
        <origin xyz="0 0 0" rpy="0 0 0"/>
        <geometry>
          <mesh filename="package://rbsherpa_hl_description/meshes/pantilt/tilt_dynamixel.stl"/>
        </geometry>
      </collision>
      <inertial>
        <origin xyz="0 0 0" rpy="0 0 0"/>
        <mass value="5"/>
        <inertia ixx="1.0" ixy="0.0" ixz="0.0" iyy="1.0" iyz="0.0" izz="1.0"/>
      </inertial>
    </link>

    <joint name="${prefix}torso_fumigator_joint" type="fixed">
      <origin xyz="0.0 0.056 0.035" rpy="0 0 0"/>
      <parent link="${prefix}torso_pantilt_tilt_link"/>
      <child link="${prefix}torso_fumigator_link"/>
    </joint>
    
    <link name="${prefix}torso_fumigator_link">
      <visual>
        <origin xyz="0 0 0" rpy="0 0 0"/>
        <geometry>
          <mesh filename="package://rbsherpa_hl_description/meshes/pantilt/sprayer.stl"/>
        </geometry>
       <material name="lightgrey">
         <color rgba="0.3 0.3 0.3 1"/>
       </material>
      </visual>
      <collision>
        <origin xyz="0 0 0" rpy="0 0 0"/>
        <geometry>
          <mesh filename="package://rbsherpa_hl_description/meshes/pantilt/sprayer.stl"/>
        </geometry>
      </collision>
      <inertial>
        <origin xyz="0 0 0" rpy="0 0 0"/>
        <mass value="5"/>
        <inertia ixx="1.0" ixy="0.0" ixz="0.0" iyy="1.0" iyz="0.0" izz="1.0"/>
      </inertial>
    </link>

  </xacro:macro>
</robot>
