<?xml version="1.0"?>
<robot name="rbsherpa_structure" xmlns:xacro="http://www.ros.org/wiki/xacro">

  <xacro:property name="M_PI" value="3.1415926535897931" />

  <xacro:macro name="gimbal" params="prefix parent *origin">

    <!-- gimbal base -->
    <joint name="${prefix}gimbal_base_joint" type="fixed">
      <parent link="${parent}"/>
      <!--origin xyz="-0.46 0.0 0.08" rpy="0 0 ${M_PI}" /-->
      <child link="${prefix}gimbal_base_link"/>
      <xacro:insert_block name="origin" />
    </joint>
    <link name="${prefix}gimbal_base_link">
    </link>

    <joint name="${prefix}gimbal_yaw_joint" type="revolute">
      <parent link="${prefix}gimbal_base_link"/>
      <origin xyz="0.0 0.0 -0.097" rpy="0 0 0" />
      <child link="${prefix}gimbal_yaw_link"/>
      <axis xyz="0 0 1"/>
      <limit lower="-1.57" upper="1.57" effort="1.0" velocity="0.5"/>
    </joint>
    <link name="${prefix}gimbal_yaw_link">
    </link>

    <!--joint name="${prefix}gimbal_first_axis_joint" type="fixed">
      <parent link="${prefix}gimbal_yaw_link"/>
      <origin xyz="-0.072 0.0 -0.026" rpy="0 0 0" />
      <child link="${prefix}gimbal_first_axis_link"/>
    </joint>
    <link name="${prefix}gimbal_first_axis_link">
    </link-->

    <joint name="${prefix}gimbal_roll_joint" type="revolute">
      <parent link="${prefix}gimbal_yaw_link"/>
      <origin xyz="-0.102 0.0 -0.200" rpy="0 0 0" />
      <child link="${prefix}gimbal_roll_link"/>
      <axis xyz="1 0 0"/>
      <limit lower="-1.57" upper="1.57" effort="1.0" velocity="0.5"/>
    </joint>
    <link name="${prefix}gimbal_roll_link">
    </link>

    <joint name="${prefix}gimbal_pitch_joint" type="revolute">
      <parent link="${prefix}gimbal_roll_link"/>
      <origin xyz="0.134 0.110 0.0" rpy="0 0 0" />
      <child link="${prefix}gimbal_pitch_link"/>
      <axis xyz="0 1 0"/>
      <limit lower="-1.57" upper="1.57" effort="1.0" velocity="0.5"/>
    </joint>
    <link name="${prefix}gimbal_pitch_link">
    </link>

    <joint name="${prefix}gimbal_camera_joint" type="fixed">
      <parent link="${prefix}gimbal_pitch_link"/>
      <origin xyz="0.0 -0.11 -0.045" rpy="0 0 0" />
      <child link="${prefix}gimbal_camera_link"/>
    </joint>
    <link name="${prefix}gimbal_camera_link">
    </link>
  
  </xacro:macro>

</robot>
