<?xml version="1.0"?>
<robot name="rbsherpa_structure" xmlns:xacro="http://www.ros.org/wiki/xacro">

  <xacro:property name="M_PI" value="3.1415926535897931" />
  <xacro:property name="deg2rad" value="0.01745329251"/>

  <xacro:macro name="structure" params="prefix parent *origin">

	<!--fixed joint -->
    <joint name="${prefix}structure_joint" type="fixed">
      <parent link="${parent}"/>
      <child link="${prefix}structure_link"/>
      <xacro:insert_block name="origin" />
    </joint>

    <link name="${prefix}structure_link">
      <visual>
        <origin xyz="0 0 0" rpy="0 0 0" />
        <geometry>
		      <mesh filename="package://rbsherpa_hl_description/meshes/structure/rbsherpa_hl_column.dae" />
        </geometry>
      </visual>

      <collision>
		    <origin xyz="0 0 0" rpy="0 0 0" />
        <geometry>
			    <mesh filename="package://rbsherpa_hl_description/meshes/structure/rbsherpa_hl_column.stl" />
        </geometry>
      </collision>

      <inertial>
        <mass value="14.92765" />
        <origin xyz="-0.0195 -0.01 -0.750" />
        <inertia  ixx="2.80754349924" ixy = "0" ixz = "0"
                  iyy="2.80407121984" iyz = "0"
                  izz="0.01374410335" />
      </inertial>

    </link>

    <!--GIRO: fixed joint -->
    <joint name="${prefix}platform_joint" type="fixed">
      <parent link="${prefix}structure_link"/>
      <origin xyz="-0.01 -0.01 0" rpy="0 0 0" />
      <child link="${prefix}platform_link"/>
      <xacro:insert_block name="origin" />
    </joint>

    <link name="${prefix}platform_link">
      <visual>
        <origin xyz="0 0 0" rpy="0 0 0" />
        <geometry>
		      <mesh filename="package://rbsherpa_hl_description/meshes/structure/rbsherpa_hl_tt_giro.dae" />
        </geometry>
      </visual>

      <collision>
		    <origin xyz="0 0 0" rpy="0 0 0" />
        <geometry>
			    <mesh filename="package://rbsherpa_hl_description/meshes/structure/rbsherpa_hl_tt_giro.stl" />
        </geometry>
      </collision>

      <inertial>
        <mass value="4.64491" />
        <origin xyz="0 0 0.004" />
        <inertia  ixx="0.13451516929" ixy = "0" ixz = "0"
                  iyy="0.00865201773" iyz = "0"
                  izz="0.14311764130" />
      </inertial>

    </link>

        <!-- PAN TILT BASE -->
    <joint name="${prefix}torso_pantilt_base_joint" type="fixed">
      <origin xyz="0.0 0.0 0.0" rpy="0 0 0"/>
      <parent link="${prefix}structure_link"/>
      <!--<parent link="${prefix}torso_base_link"/>-->
      <child link="${prefix}torso_pantilt_base_link"/>
      <axis xyz="0 0 1"/>
    </joint>
    
    <link name="${prefix}torso_pantilt_base_link">
      <visual>
        <origin xyz="0 0 0" rpy="0 0 0"/>
        <geometry>
          <mesh filename="package://rbsherpa_hl_description/meshes/pantilt/base.stl"/>
        </geometry>
       <material name="lightgrey">
         <color rgba="0.3 0.3 0.3 1"/>
       </material>
      </visual>
      <collision>
        <origin xyz="0 0 0" rpy="0 0 0"/>
        <geometry>
          <mesh filename="package://rbsherpa_hl_description/meshes/pantilt/base.stl"/>
        </geometry>
      </collision>
      <inertial>
        <origin xyz="0 0 0" rpy="0 0 0"/>
        <mass value="5"/>
        <inertia ixx="1.0" ixy="0.0" ixz="0.0" iyy="1.0" iyz="0.0" izz="1.0"/>
      </inertial>
    </link>

    <!-- PAN JOINT/LINK -->
    <joint name="${prefix}torso_pantilt_pan_base_joint" type="fixed">
      <origin xyz="0.0 0.0 0.0" rpy="0 0 0"/>
      <parent link="${prefix}torso_pantilt_base_link"/>
      <child link="${prefix}torso_pantilt_pan_base_link"/>
      <axis xyz="0 0 1"/>
    </joint>
    
    <link name="${prefix}torso_pantilt_pan_base_link">
      <visual>
        <origin xyz="0 0 0" rpy="0 0 0"/>
        <geometry>
          <mesh filename="package://rbsherpa_hl_description/meshes/pantilt/dynamixel_l42.stl"/>
        </geometry>
       <material name="lightgrey">
         <color rgba="0.3 0.3 0.3 1"/>
       </material>
      </visual>
      <collision>
        <origin xyz="0 0 0" rpy="0 0 0"/>
        <geometry>
          <mesh filename="package://rbsherpa_hl_description/meshes/pantilt/dynamixel_l42.stl"/>
        </geometry>
      </collision>
      <inertial>
        <origin xyz="0 0 0" rpy="0 0 0"/>
        <mass value="5"/>
        <inertia ixx="1.0" ixy="0.0" ixz="0.0" iyy="1.0" iyz="0.0" izz="1.0"/>
      </inertial>
    </link>
    
    <joint name="${prefix}torso_pantilt_pan_joint" type="revolute">
      <origin xyz="0.0 0.0 0.111" rpy="0 0 0"/>
      <parent link="${prefix}torso_pantilt_pan_base_link"/>
      <child link="${prefix}torso_pantilt_pan_link"/>
      <axis xyz="0 0 1"/>
      <limit lower="${-360*deg2rad}" upper="${360*deg2rad}" effort="100" velocity="100"/>
      <dynamics friction="1000" damping="1000"/>
    </joint>
	

    
    <link name="${prefix}torso_pantilt_pan_link">
      <visual>
        <origin xyz="0 0 0" rpy="0 0 0"/>
        <geometry>
          <mesh filename="package://rbsherpa_hl_description/meshes/pantilt/pan.stl"/>
        </geometry>
       <material name="lightgrey">
         <color rgba="0.3 0.3 0.3 1"/>
       </material>
      </visual>
      <collision>
        <origin xyz="0 0 0" rpy="0 0 0"/>
        <geometry>
          <mesh filename="package://rbsherpa_hl_description/meshes/pantilt/pan.stl"/>
        </geometry>
      </collision>
      <inertial>
        <origin xyz="0 0 0" rpy="0 0 0"/>
        <mass value="5"/>
        <inertia ixx="1.0" ixy="0.0" ixz="0.0" iyy="1.0" iyz="0.0" izz="1.0"/>
      </inertial>
    </link>
    
    
    <!-- TILT JOINT/LINK -->
    <joint name="${prefix}torso_pantilt_tilt_joint" type="revolute">
      <origin xyz="0.0 -0.027 0.0" rpy="${-90*deg2rad} 0 0"/>
      <parent link="${prefix}torso_pantilt_pan_link"/>
      <child link="${prefix}torso_pantilt_tilt_base_link"/>
      <axis xyz="0 0 1"/>
      <limit lower="${-360*deg2rad}" upper="${360*deg2rad}" effort="100" velocity="100"/>
      <dynamics friction="1000" damping="1000"/>
    </joint>
	

    
    <link name="${prefix}torso_pantilt_tilt_base_link">
      <visual>
        <origin xyz="0 0 0" rpy="0 0 0"/>
        <geometry>
          <mesh filename="package://rbsherpa_hl_description/meshes/pantilt/dynamixel_l42.stl"/>
        </geometry>
       <material name="lightgrey">
         <color rgba="0.3 0.3 0.3 1"/>
       </material>
      </visual>
      <collision>
        <origin xyz="0 0 0" rpy="0 0 0"/>
        <geometry>
          <mesh filename="package://rbsherpa_hl_description/meshes/pantilt/dynamixel_l42.stl"/>
        </geometry>
      </collision>
      <inertial>
        <origin xyz="0 0 0" rpy="0 0 0"/>
        <mass value="5"/>
        <inertia ixx="1.0" ixy="0.0" ixz="0.0" iyy="1.0" iyz="0.0" izz="1.0"/>
      </inertial>
    </link>
    
    <joint name="${prefix}torso_pantilt_tilt_support_joint" type="fixed">
      <origin xyz="0.0 0.0 0.0" rpy="${90*deg2rad} 0 0"/>
      <parent link="${prefix}torso_pantilt_tilt_base_link"/>
      <child link="${prefix}torso_pantilt_tilt_support_link"/>
      <axis xyz="0 0 1"/>
    </joint>
    
    <link name="${prefix}torso_pantilt_tilt_support_link">
      <visual>
        <origin xyz="0 0 0" rpy="0 0 0"/>
        <geometry>
          <mesh filename="package://rbsherpa_hl_description/meshes/pantilt/tilt_support.stl"/>
        </geometry>
       <material name="lightgrey">
         <color rgba="0.3 0.3 0.3 1"/>
       </material>
      </visual>
      <collision>
        <origin xyz="0 0 0" rpy="0 0 0"/>
        <geometry>
          <mesh filename="package://rbsherpa_hl_description/meshes/pantilt/tilt_support.stl"/>
        </geometry>
      </collision>
      <inertial>
        <origin xyz="0 0 0" rpy="0 0 0"/>
        <mass value="5"/>
        <inertia ixx="1.0" ixy="0.0" ixz="0.0" iyy="1.0" iyz="0.0" izz="1.0"/>
      </inertial>
    </link>
    
    <joint name="${prefix}torso_pantilt_tilt_fixed_joint" type="fixed">
      <!--<origin xyz="0.0 0.027 0.027" rpy="0 0 0"/>-->
      <origin xyz="0.0 -0.027 0.027" rpy="${90*deg2rad} 0 0"/>
      <parent link="${prefix}torso_pantilt_tilt_base_link"/>
      <child link="${prefix}torso_pantilt_tilt_link"/>
    </joint>
    
    <link name="${prefix}torso_pantilt_tilt_link">
      <visual>
        <origin xyz="0 0 0" rpy="0 0 0"/>
        <geometry>
          <mesh filename="package://rbsherpa_hl_description/meshes/pantilt/tilt.stl"/>
        </geometry>
       <material name="lightgrey">
         <color rgba="0.3 0.3 0.3 1"/>
       </material>
      </visual>
      <collision>
        <origin xyz="0 0 0" rpy="0 0 0"/>
        <geometry>
          <mesh filename="package://rbsherpa_hl_description/meshes/pantilt/tilt.stl"/>
        </geometry>
      </collision>
      <inertial>
        <origin xyz="0 0 0" rpy="0 0 0"/>
        <mass value="5"/>
        <inertia ixx="1.0" ixy="0.0" ixz="0.0" iyy="1.0" iyz="0.0" izz="1.0"/>
      </inertial>
    </link>
    
    <joint name="${prefix}torso_pantilt_joint" type="fixed">
      <origin xyz="0.0 0.0 0.003" rpy="0 0 0"/>
      <parent link="${prefix}torso_pantilt_tilt_link"/>
      <child link="${prefix}torso_pantilt_link"/>
    </joint>
    
    <link name="${prefix}torso_pantilt_link">
      <visual>
        <origin xyz="0 0 0" rpy="0 0 0"/>
        <geometry>
          <mesh filename="package://rbsherpa_hl_description/meshes/pantilt/pantilt.stl"/>
        </geometry>
       <material name="lightgrey">
         <color rgba="0.3 0.3 0.3 1"/>
       </material>
      </visual>
      <collision>
        <origin xyz="0 0 0" rpy="0 0 0"/>
        <geometry>
          <mesh filename="package://rbsherpa_hl_description/meshes/pantilt/pantilt.stl"/>
        </geometry>
      </collision>
      <inertial>
        <origin xyz="0 0 0" rpy="0 0 0"/>
        <mass value="5"/>
        <inertia ixx="1.0" ixy="0.0" ixz="0.0" iyy="1.0" iyz="0.0" izz="1.0"/>
      </inertial>
    </link>
    

  </xacro:macro>

</robot>
